Workbook

Sheet Abrechnung
B2: Reisekostenabrechnung
B3: StefanAI Solutions GmbH · Graeffstr. 22, 50823 Köln
B5: Gelb hinterlegte Felder ausfüllen. Alles Übrige berechnet sich automatisch.
B7: 1. Angaben zur Reise
B8: Name
B9: Reiseziel (Ort)
B10: Kunde / Anlass
B11: Abreise: Datum | F11: Dauer gesamt: | G11: =IF(OR(C11="",C13=""),"",TEXT((C13+C14)-(C11+C12),"[h]:mm")&" Std.")
B12: Abreise: Uhrzeit
B13: Rückkehr: Datum
B14: Rückkehr: Uhrzeit
B16: 2. Verpflegungspauschale (keine Belege erforderlich)
B17: Datum | C17: Abwesenheit | D17: Frühstück gestellt | E17: Mittag gestellt | F17: Abend gestellt | G17: Grundsatz | H17: Kürzung | I17: Pauschale
G18: =IF(C18="","",IF(C18="ganzer Tag",Sätze!$C$4,IF(OR(C18="An-/Abreisetag",C18="über 8 Std."),Sätze!$C$5,0))) | H18: =IF(C18="","",MIN(G18,IF(D18="ja",Sätze!$C$8,0)+IF(E18="ja",Sätze!$C$9,0)+IF(F18="ja",Sätze!$C$10,0))) | I18: =IF(C18="","",G18-H18)
G19: =IF(C19="","",IF(C19="ganzer Tag",Sätze!$C$4,IF(OR(C19="An-/Abreisetag",C19="über 8 Std."),Sätze!$C$5,0))) | H19: =IF(C19="","",MIN(G19,IF(D19="ja",Sätze!$C$8,0)+IF(E19="ja",Sätze!$C$9,0)+IF(F19="ja",Sätze!$C$10,0))) | I19: =IF(C19="","",G19-H19)
G20: =IF(C20="","",IF(C20="ganzer Tag",Sätze!$C$4,IF(OR(C20="An-/Abreisetag",C20="über 8 Std."),Sätze!$C$5,0))) | H20: =IF(C20="","",MIN(G20,IF(D20="ja",Sätze!$C$8,0)+IF(E20="ja",Sätze!$C$9,0)+IF(F20="ja",Sätze!$C$10,0))) | I20: =IF(C20="","",G20-H20)
G21: =IF(C21="","",IF(C21="ganzer Tag",Sätze!$C$4,IF(OR(C21="An-/Abreisetag",C21="über 8 Std."),Sätze!$C$5,0))) | H21: =IF(C21="","",MIN(G21,IF(D21="ja",Sätze!$C$8,0)+IF(E21="ja",Sätze!$C$9,0)+IF(F21="ja",Sätze!$C$10,0))) | I21: =IF(C21="","",G21-H21)
G22: =IF(C22="","",IF(C22="ganzer Tag",Sätze!$C$4,IF(OR(C22="An-/Abreisetag",C22="über 8 Std."),Sätze!$C$5,0))) | H22: =IF(C22="","",MIN(G22,IF(D22="ja",Sätze!$C$8,0)+IF(E22="ja",Sätze!$C$9,0)+IF(F22="ja",Sätze!$C$10,0))) | I22: =IF(C22="","",G22-H22)
G23: =IF(C23="","",IF(C23="ganzer Tag",Sätze!$C$4,IF(OR(C23="An-/Abreisetag",C23="über 8 Std."),Sätze!$C$5,0))) | H23: =IF(C23="","",MIN(G23,IF(D23="ja",Sätze!$C$8,0)+IF(E23="ja",Sätze!$C$9,0)+IF(F23="ja",Sätze!$C$10,0))) | I23: =IF(C23="","",G23-H23)
G24: =IF(C24="","",IF(C24="ganzer Tag",Sätze!$C$4,IF(OR(C24="An-/Abreisetag",C24="über 8 Std."),Sätze!$C$5,0))) | H24: =IF(C24="","",MIN(G24,IF(D24="ja",Sätze!$C$8,0)+IF(E24="ja",Sätze!$C$9,0)+IF(F24="ja",Sätze!$C$10,0))) | I24: =IF(C24="","",G24-H24)
G25: =IF(C25="","",IF(C25="ganzer Tag",Sätze!$C$4,IF(OR(C25="An-/Abreisetag",C25="über 8 Std."),Sätze!$C$5,0))) | H25: =IF(C25="","",MIN(G25,IF(D25="ja",Sätze!$C$8,0)+IF(E25="ja",Sätze!$C$9,0)+IF(F25="ja",Sätze!$C$10,0))) | I25: =IF(C25="","",G25-H25)
G26: =IF(C26="","",IF(C26="ganzer Tag",Sätze!$C$4,IF(OR(C26="An-/Abreisetag",C26="über 8 Std."),Sätze!$C$5,0))) | H26: =IF(C26="","",MIN(G26,IF(D26="ja",Sätze!$C$8,0)+IF(E26="ja",Sätze!$C$9,0)+IF(F26="ja",Sätze!$C$10,0))) | I26: =IF(C26="","",G26-H26)
G27: =IF(C27="","",IF(C27="ganzer Tag",Sätze!$C$4,IF(OR(C27="An-/Abreisetag",C27="über 8 Std."),Sätze!$C$5,0))) | H27: =IF(C27="","",MIN(G27,IF(D27="ja",Sätze!$C$8,0)+IF(E27="ja",Sätze!$C$9,0)+IF(F27="ja",Sätze!$C$10,0))) | I27: =IF(C27="","",G27-H27)
H28: Summe Verpflegung | I28: =SUM(I18:I27) -> 0
B29: Kürzung nur, wenn die Mahlzeit von Arbeitgeber, Kunde oder Hotel gestellt wurde. Sätze siehe Blatt „Sätze“.
B31: 3. Fahrtkosten (Beleg beifügen)
B32: Datum | C32: Verkehrsmittel / Strecke | I32: Betrag
B38: Privat-Pkw | C38: gefahrene km: | E38: × Satz je km | F38: =Sätze!$C$13 -> 0.3 | I38: =IF(D38="",0,D38*F38) -> 0
B40: 4. Übernachtung (Rechnung auf die GmbH)
B41: Datum | C41: Hotel / Ort | I41: Betrag
B48: 5. Reisenebenkosten (Beleg beifügen)
B49: Datum | C49: Art (Parken, ÖPNV, Maut …) | I49: Betrag
B56: 6. Erstattungsbetrag
B57: Verpflegungspauschale (steuerfrei) | I57: =I28 -> 0
B58: Fahrtkosten (Belege) | I58: =SUM(I33:I37) -> 0
B59: Fahrtkosten Privat-Pkw | I59: =I38 -> 0
B60: Übernachtung | I60: =SUM(I42:I46) -> 0
B61: Reisenebenkosten | I61: =SUM(I50:I54) -> 0
B62: Gesamterstattung | I62: =SUM(I57:I61) -> 0
B64: Anzahl beigefügter Belege:
...

Sheet Sätze
B2: Gesetzliche Sätze (Inland)
B3: Verpflegungspauschale
B4: Voller Reisetag (24 Std. abwesend) | C4: 28
B5: An-/Abreisetag bzw. eintägig über 8 Std. | C5: 14
B6: Abwesenheit unter 8 Std. | C6: 0
B7: Kürzung bei gestellten Mahlzeiten
B8: Frühstück (20 % von 28 €) | C8: 5.6
B9: Mittagessen (40 % von 28 €) | C9: 11.2
B10: Abendessen (40 % von 28 €) | C10: 11.2
B12: Fahrtkosten
B13: Kilometerpauschale Privat-Pkw | C13: 0.3
B14: Zuschlag je mitgenommener Person | C14: 0.02
B16: Rechtsgrundlage: § 9 Abs. 4a EStG. Inlandssätze seit 2020 unverändert, auch 2026.
B17: Ändert der Gesetzgeber die Sätze, hier anpassen – die Abrechnung rechnet automatisch neu.
B19: Auslandsreisen: länderspezifische Sätze des BMF, hier nicht hinterlegt.
